Workbook

Sheet Обзор
A1: Luxhommè — Яндекс Директ на сайт: семантика, объявления, UTM (15 товаров)
A3: Параметры
A4: Сайт | B4: https://luxhomme.store
A5: Промокод | B5: DIRECT20
A6: Скидка | B6: 20% на все товары при заказе на сайте
A7: География | B7: Вся Россия
A8: Кампании | B8: Поиск по товарам · Сети (РСЯ, ЕПК) · Товарная по фиду
A9: Факты о товарах | B9: Карточки luxhomme.store, снято 09.10.2026
A10: Частотности | B10: Только Aqvion Pro — из файла семантики клиента (research/semantika-vertikalnyj-moyushhij-pylesos.csv). По остальным не снимались
A11: Конкуренты | B11: Запросы с брендами конкурентов — в минус-словах
A12: Бренд Luxhommè | B12: В минус-словах: брендовые запросы идут в действующую брендовую кампанию
A14: Структура кампаний
A15: Кампания | B15: Тип / площадки | C15: Группы | D15: utm_campaign | E15: Стратегия на старте | F15: Где в файле
A16: Lux | Поиск | Пылесосы | B16: ЕПК, только поиск | C16: Aqvion Pro, Cleneo Pro, Aerlyn | D16: lux_search_pylesosy_{campaign_id} | E16: Максимум кликов с недельным бюджетом → Максимум конверсий по цели «Заказ» после накопления конверсий | F16: Листы товаров, «Импорт Поиск»
A17: Lux | Поиск | Паровые швабры | B17: ЕПК, только поиск | C17: EcoSteam Pro, AirSteam Pro, SC-100 Max | D17: lux_search_shvabry_{campaign_id} | E17: Максимум кликов с недельным бюджетом → Максимум конверсий по цели «Заказ» после накопления конверсий | F17: Листы товаров, «Импорт Поиск»
A18: Lux | Поиск | Кофемашины | B18: ЕПК, только поиск | C18: CoffeeMaker Classic, Caffio Professional, CremaX | D18: lux_search_kofe_{campaign_id} | E18: Максимум кликов с недельным бюджетом → Максимум конверсий по цели «Заказ» после накопления конверсий | F18: Листы товаров, «Импорт Поиск»
A19: Lux | Поиск | Аэрогрили | B19: ЕПК, только поиск | C19: AirChef, AirChef Dual Pro | D19: lux_search_aerogrili_{campaign_id} | E19: Максимум кликов с недельным бюджетом → Максимум конверсий по цели «Заказ» после накопления конверсий | F19: Листы товаров, «Импорт Поиск»
A20: Lux | Поиск | Виброплатформы | B20: ЕПК, только поиск | C20: uFit 2D Standard, uFit 2D Pro, uFit 3D Max | D20: lux_search_vibro_{campaign_id} | E20: Максимум кликов с недельным бюджетом → Максимум конверсий по цели «Заказ» после накопления конверсий | F20: Листы товаров, «Импорт Поиск»
A21: Lux | Поиск | Роботы-мойщики окон | B21: ЕПК, только поиск | C21: uClean Max | D21: lux_search_okna_{campaign_id} | E21: Максимум кликов с недельным бюджетом → Максимум конверсий по цели «Заказ» после накопления конверсий | F21: Листы товаров, «Импорт Поиск»
A22: Lux | Сети | Пылесосы | B22: ЕПК, только РСЯ: автотаргетинг + фразы, картинки | C22: Aqvion Pro, Cleneo Pro, Aerlyn | D22: lux_epk_pylesosy_{campaign_id} | E22: Как в поиске | F22: Листы товаров (блок РСЯ), «Импорт Сети»
A23: Lux | Сети | Паровые швабры | B23: ЕПК, только РСЯ: автотаргетинг + фразы, картинки | C23: EcoSteam Pro, AirSteam Pro, SC-100 Max | D23: lux_epk_shvabry_{campaign_id} | E23: Как в поиске | F23: Листы товаров (блок РСЯ), «Импорт Сети»
A24: Lux | Сети | Кофемашины | B24: ЕПК, только РСЯ: автотаргетинг + фразы, картинки | C24: CoffeeMaker Classic, Caffio Professional, CremaX | D24: lux_epk_kofe_{campaign_id} | E24: Как в поиске | F24: Листы товаров (блок РСЯ), «Импорт Сети»
A25: Lux | Сети | Аэрогрили | B25: ЕПК, только РСЯ: автотаргетинг + фразы, картинки | C25: AirChef, AirChef Dual Pro | D25: lux_epk_aerogrili_{campaign_id} | E25: Как в поиске | F25: Листы товаров (блок РСЯ), «Импорт Сети»
A26: Lux | Сети | Виброплатформы | B26: ЕПК, только РСЯ: автотаргетинг + фразы, картинки | C26: uFit 2D Standard, uFit 2D Pro, uFit 3D Max | D26: lux_epk_vibro_{campaign_id} | E26: Как в поиске | F26: Листы товаров (блок РСЯ), «Импорт Сети»
... A28: Lux | Товарная | Фид | B28: Товарная кампания: поиск + РСЯ | C28: 15 офферов из фида | D28: lux_feed_{campaign_id} | E28: Как в поиске | F28: «Фид», файл luxhomme-direct-feed.yml
A30: UTM-разметка
A31: Параметр | B31: Значение | C31: Что даёт
A32: utm_source | B32: yandex | C32: Источник
A33: utm_medium | B33: cpc | C33: Платный трафик
A34: utm_campaign | B34: lux_<search|epk|feed>_<категория>_{campaign_id} | C34: Тип кампании, категория, ID кампании
A35: utm_content | B35: <модель>_{ad_id}_{source_type} | C35: Товар, ID объявления, поиск/сети
A36: utm_term | B36: {keyword} | C36: Ключевая фраза
A37: Быстрые ссылки | B37: в utm_content добавлено _sitelink | C37: Отделить переходы по быстрым ссылкам
A39: Перед запуском
A40: ☐ | B40: Завести на сайте промокод DIRECT20: −20% на все товары; указать условие на сайте (баннер или строка в карточке) — модерация сверяет скидку с посадочной.
A41: ☐ | B41: Гостевое оформление заказа и срок/стоимость доставки до входа в аккаунт (UI/UX-аудит, разделы 1–2).
A42: ☐ | B42: Гарантия: в карточках 3 года (EcoSteam Pro — 12 месяцев, uFit 2D Standard — 2 года), на /service — 12 месяцев. Привести к одному сроку; в объявлениях срок взят из карточки.
A43: ☐ | B43: Бесплатную доставку не обещать: на /delivery стоимость не рассчитывается автоматически.
A44: ☐ | B44: CremaX нет в sitemap — добавить.
A45: ☐ | B45: На /returns продавец — ИП, в подвале сайта — ООО «САУДАГАР Е-КОМ»: указать одного продавца.
...

Sheet Товары
A1: Скидка | B1: 0.2
A3: № | B3: Товар | C3: Категория | D3: SKU | E3: Цена, ₽ | F3: С промокодом, ₽ | G3: Гарантия | H3: Страница | I3: Ссылка Поиск (UTM) | J3: Ссылка Сети (UTM) | K3: Ссылка Фид (UTM)
A4: 1 | B4: Вертикальный моющий пылесос Aqvion Pro | C4: Пылесосы | D4: VACCLWASH | E4: 19990 | F4: =ROUND(E4*(1-$B$1),0) | G4: 3 года | H4: https://luxhomme.store/products/vertikalnyj-moyushhij-pylesos-aqvion-pro | I4: https://luxhomme.store/products/vertikalnyj-moyushhij-pylesos-aqvion-pro?utm_source=yandex&utm_medium=cpc&utm_campaign=lux_search_pylesosy_{campaign_id}&utm_content=aqvion-pro_{ad_id}_{source_type}&utm_term={keyword} | J4: https://luxhomme.store/products/vertikalnyj-moyushhij-pylesos-aqvion-pro?utm_source=yandex&utm_medium=cpc&utm_campaign=lux_epk_pylesosy_{campaign_id}&utm_content=aqvion-pro_{ad_id}_{source_type}&utm_term={keyword} | K4: https://luxhomme.store/products/vertikalnyj-moyushhij-pylesos-aqvion-pro?utm_source=yandex&utm_medium=cpc&utm_campaign=lux_feed_{campaign_id}&utm_content=aqvion-pro_{ad_id}_{source_type}&utm_term={keyword}
A5: 2 | B5: Компактный моющий пылесос Cleneo Pro | C5: Пылесосы | D5: VACCLCOMPACT | E5: 16990 | F5: =ROUND(E5*(1-$B$1),0) | G5: 3 года | H5: https://luxhomme.store/products/kompaktnyj-moyushhij-pylesos-cleneo-pro | I5: https://luxhomme.store/products/kompaktnyj-moyushhij-pylesos-cleneo-pro?utm_source=yandex&utm_medium=cpc&utm_campaign=lux_search_pylesosy_{campaign_id}&utm_content=cleneo-pro_{ad_id}_{source_type}&utm_term={keyword} | J5: https://luxhomme.store/products/kompaktnyj-moyushhij-pylesos-cleneo-pro?utm_source=yandex&utm_medium=cpc&utm_campaign=lux_epk_pylesosy_{campaign_id}&utm_content=cleneo-pro_{ad_id}_{source_type}&utm_term={keyword} | K5: https://luxhomme.store/products/kompaktnyj-moyushhij-pylesos-cleneo-pro?utm_source=yandex&utm_medium=cpc&utm_campaign=lux_feed_{campaign_id}&utm_content=cleneo-pro_{ad_id}_{source_type}&utm_term={keyword}
A6: 3 | B6: Вертикальный сухой пылесос Aerlyn | C6: Пылесосы | D6: VACCLDRY | E6: 15990 | F6: =ROUND(E6*(1-$B$1),0) | G6: 3 года | H6: https://luxhomme.store/products/vertikalnyj-suhoj-pylesos-aerlyn | I6: https://luxhomme.store/products/vertikalnyj-suhoj-pylesos-aerlyn?utm_source=yandex&utm_medium=cpc&utm_campaign=lux_search_pylesosy_{campaign_id}&utm_content=aerlyn_{ad_id}_{source_type}&utm_term={keyword} | J6: https://luxhomme.store/products/vertikalnyj-suhoj-pylesos-aerlyn?utm_source=yandex&utm_medium=cpc&utm_campaign=lux_epk_pylesosy_{campaign_id}&utm_content=aerlyn_{ad_id}_{source_type}&utm_term={keyword} | K6: https://luxhomme.store/products/vertikalnyj-suhoj-pylesos-aerlyn?utm_source=yandex&utm_medium=cpc&utm_campaign=lux_feed_{campaign_id}&utm_content=aerlyn_{ad_id}_{source_type}&utm_term={keyword}
A7: 4 | B7: Паровая швабра Luxhommè EcoSteam Pro | C7: Паровые швабры | D7: SHVPAREKCHB2 | E7: 5990 | F7: =ROUND(E7*(1-$B$1),0) | G7: 12 месяцев | H7: https://luxhomme.store/products/ecosteam-pro | I7: https://luxhomme.store/products/ecosteam-pro?utm_source=yandex&utm_medium=cpc&utm_campaign=lux_search_shvabry_{campaign_id}&utm_content=ecosteam-pro_{ad_id}_{source_type}&utm_term={keyword} | J7: https://luxhomme.store/products/ecosteam-pro?utm_source=yandex&utm_medium=cpc&utm_campaign=lux_epk_shvabry_{campaign_id}&utm_content=ecosteam-pro_{ad_id}_{source_type}&utm_term={keyword} | K7: https://luxhomme.store/products/ecosteam-pro?utm_source=yandex&utm_medium=cpc&utm_campaign=lux_feed_{campaign_id}&utm_content=ecosteam-pro_{ad_id}_{source_type}&utm_term={keyword}
A8: 5 | B8: Паровая швабра Luxhommè AirSteam Pro | C8: Паровые швабры | D8: SHVPAR3D | E8: 10990 | F8: =ROUND(E8*(1-$B$1),0) | G8: 3 года | H8: https://luxhomme.store/products/steamly-pro | I8: https://luxhomme.store/products/steamly-pro?utm_source=yandex&utm_medium=cpc&utm_campaign=lux_search_shvabry_{campaign_id}&utm_content=airsteam-pro_{ad_id}_{source_type}&utm_term={keyword} | J8: https://luxhomme.store/products/steamly-pro?utm_source=yandex&utm_medium=cpc&utm_campaign=lux_epk_shvabry_{campaign_id}&utm_content=airsteam-pro_{ad_id}_{source_type}&utm_term={keyword} | K8: https://luxhomme.store/products/steamly-pro?utm_source=yandex&utm_medium=cpc&utm_campaign=lux_feed_{campaign_id}&utm_content=airsteam-pro_{ad_id}_{source_type}&utm_term={keyword}
A9: 6 | B9: Паровая швабра Luxhommè SC-100 Max | C9: Паровые швабры | D9: SHVPAR7V1CH | E9: 7990 | F9: =ROUND(E9*(1-$B$1),0) | G9: 3 года | H9: https://luxhomme.store/products/sc-100 | I9: https://luxhomme.store/products/sc-100?utm_source=yandex&utm_medium=cpc&utm_campaign=lux_search_shvabry_{campaign_id}&utm_content=sc-100-max_{ad_id}_{source_type}&utm_term={keyword} | J9: https://luxhomme.store/products/sc-100?utm_source=yandex&utm_medium=cpc&utm_campaign=lux_epk_shvabry_{campaign_id}&utm_content=sc-100-max_{ad_id}_{source_type}&utm_term={keyword} | K9: https://luxhomme.store/products/sc-100?utm_source=yandex&utm_medium=cpc&utm_campaign=lux_feed_{campaign_id}&utm_content=sc-100-max_{ad_id}_{source_type}&utm_term={keyword}
A10: 7 | B10: Кофемашина Luxhommè CoffeeMaker Classic | C10: Кофемашины | D10: COFMASHCAP4V1 | E10: 9990 | F10: =ROUND(E10*(1-$B$1),0) | G10: 3 года | H10: https://luxhomme.store/products/coffee | I10: https://luxhomme.store/products/coffee?utm_source=yandex&utm_medium=cpc&utm_campaign=lux_search_kofe_{campaign_id}&utm_content=coffeemaker-classic_{ad_id}_{source_type}&utm_term={keyword} | J10: https://luxhomme.store/products/coffee?utm_source=yandex&utm_medium=cpc&utm_campaign=lux_epk_kofe_{campaign_id}&utm_content=coffeemaker-classic_{ad_id}_{source_type}&utm_term={keyword} | K10: https://luxhomme.store/products/coffee?utm_source=yandex&utm_medium=cpc&utm_campaign=lux_feed_{campaign_id}&utm_content=coffeemaker-classic_{ad_id}_{source_type}&utm_term={keyword}
A11: 8 | B11: Кофемашина рожковая Luxhommè Caffio Professional | C11: Кофемашины | D11: COFMASHROZH | E11: 17990 | F11: =ROUND(E11*(1-$B$1),0) | G11: 3 года | H11: https://luxhomme.store/products/caffio-professional | I11: https://luxhomme.store/products/caffio-professional?utm_source=yandex&utm_medium=cpc&utm_campaign=lux_search_kofe_{campaign_id}&utm_content=caffio-professional_{ad_id}_{source_type}&utm_term={keyword} | J11: https://luxhomme.store/products/caffio-professional?utm_source=yandex&utm_medium=cpc&utm_campaign=lux_epk_kofe_{campaign_id}&utm_content=caffio-professional_{ad_id}_{source_type}&utm_term={keyword} | K11: https://luxhomme.store/products/caffio-professional?utm_source=yandex&utm_medium=cpc&utm_campaign=lux_feed_{campaign_id}&utm_content=caffio-professional_{ad_id}_{source_type}&utm_term={keyword}
A12: 9 | B12: Кофемашина автоматическая зерновая с капучинатором и кофемолкой CremaX | C12: Кофемашины | D12: COFMASHPOMOL | E12: 47990 | F12: =ROUND(E12*(1-$B$1),0) | G12: 3 года | H12: https://luxhomme.store/products/cremax | I12: https://luxhomme.store/products/cremax?utm_source=yandex&utm_medium=cpc&utm_campaign=lux_search_kofe_{campaign_id}&utm_content=cremax_{ad_id}_{source_type}&utm_term={keyword} | J12: https://luxhomme.store/products/cremax?utm_source=yandex&utm_medium=cpc&utm_campaign=lux_epk_kofe_{campaign_id}&utm_content=cremax_{ad_id}_{source_type}&utm_term={keyword} | K12: https://luxhomme.store/products/cremax?utm_source=yandex&utm_medium=cpc&utm_campaign=lux_feed_{campaign_id}&utm_content=cremax_{ad_id}_{source_type}&utm_term={keyword}
A13: 10 | B13: Аэрогриль Luxhommè AirChef | C13: Аэрогрили | D13: AEROGRIL55L2 | E13: 5990 | F13: =ROUND(E13*(1-$B$1),0) | G13: 3 года | H13: https://luxhomme.store/products/airgrill | I13: https://luxhomme.store/products/airgrill?utm_source=yandex&utm_medium=cpc&utm_campaign=lux_search_aerogrili_{campaign_id}&utm_content=airchef_{ad_id}_{source_type}&utm_term={keyword} | J13: https://luxhomme.store/products/airgrill?utm_source=yandex&utm_medium=cpc&utm_campaign=lux_epk_aerogrili_{campaign_id}&utm_content=airchef_{ad_id}_{source_type}&utm_term={keyword} | K13: https://luxhomme.store/products/airgrill?utm_source=yandex&utm_medium=cpc&utm_campaign=lux_feed_{campaign_id}&utm_content=airchef_{ad_id}_{source_type}&utm_term={keyword}
A14: 11 | B14: Аэрогриль Luxhommè AirChef Dual Pro (2 чаши) | C14: Аэрогрили | D14: AEROGRIL2CHASHI | E14: 16990 | F14: =ROUND(E14*(1-$B$1),0) | G14: 3 года | H14: https://luxhomme.store/products/airgrill-dual-pro | I14: https://luxhomme.store/products/airgrill-dual-pro?utm_source=yandex&utm_medium=cpc&utm_campaign=lux_search_aerogrili_{campaign_id}&utm_content=airchef-dual-pro_{ad_id}_{source_type}&utm_term={keyword} | J14: https://luxhomme.store/products/airgrill-dual-pro?utm_source=yandex&utm_medium=cpc&utm_campaign=lux_epk_aerogrili_{campaign_id}&utm_content=airchef-dual-pro_{ad_id}_{source_type}&utm_term={keyword} | K14: https://luxhomme.store/products/airgrill-dual-pro?utm_source=yandex&utm_medium=cpc&utm_campaign=lux_feed_{campaign_id}&utm_content=airchef-dual-pro_{ad_id}_{source_type}&utm_term={keyword}
A15: 12 | B15: Виброплатформа uFit 2D Standard | C15: Виброплатформы | D15: VIPLATB | E15: 6190 | F15: =ROUND(E15*(1-$B$1),0) | G15: 2 года | H15: https://luxhomme.store/products/ufit-2d | I15: https://luxhomme.store/products/ufit-2d?utm_source=yandex&utm_medium=cpc&utm_campaign=lux_search_vibro_{campaign_id}&utm_content=ufit-2d_{ad_id}_{source_type}&utm_term={keyword} | J15: https://luxhomme.store/products/ufit-2d?utm_source=yandex&utm_medium=cpc&utm_campaign=lux_epk_vibro_{campaign_id}&utm_content=ufit-2d_{ad_id}_{source_type}&utm_term={keyword} | K15: https://luxhomme.store/products/ufit-2d?utm_source=yandex&utm_medium=cpc&utm_campaign=lux_feed_{campaign_id}&utm_content=ufit-2d_{ad_id}_{source_type}&utm_term={keyword}
... A18: 15 | B18: Робот мойщик Luxhommè uClean Max | C18: Роботы-мойщики окон | D18: ROBOTOKONKVADR | E18: 9990 | F18: =ROUND(E18*(1-$B$1),0) | G18: 3 года | H18: https://luxhomme.store/products/window | I18: https://luxhomme.store/products/window?utm_source=yandex&utm_medium=cpc&utm_campaign=lux_search_okna_{campaign_id}&utm_content=uclean-max_{ad_id}_{source_type}&utm_term={keyword} | J18: https://luxhomme.store/products/window?utm_source=yandex&utm_medium=cpc&utm_campaign=lux_epk_okna_{campaign_id}&utm_content=uclean-max_{ad_id}_{source_type}&utm_term={keyword} | K18: https://luxhomme.store/products/window?utm_source=yandex&utm_medium=cpc&utm_campaign=lux_feed_{campaign_id}&utm_content=uclean-max_{ad_id}_{source_type}&utm_term={keyword}

Sheet Aqvion Pro
A1: Вертикальный моющий пылесос Aqvion Pro
A2: Страница | B2: https://luxhomme.store/products/vertikalnyj-moyushhij-pylesos-aqvion-pro
A3: SKU | B3: VACCLWASH
A4: Цена, ₽ | B4: 19990
A5: С промокодом, ₽ | B5: =ROUND(B4*(1-Товары!$B$1),0)
A6: Промокод | B6: DIRECT20
A7: Категория | B7: Пылесосы
A9: УТП (факты из карточки)
A10: • | B10: Сухая и влажная уборка 2 в 1
A11: • | B11: Беспроводной, аккумулятор 5000 мАч
A12: • | B12: До 55–60 минут в эко-режиме, 28 минут на максимуме
A13: • | B13: Всасывание 15 000 Па
A14: • | B14: Самоочистка и сушка на базе
A15: • | B15: Электролиз воды
A16: • | B16: LED-подсветка, наклон 170°
A17: • | B17: Голосовые подсказки, IPX4
A18: • | B18: Баки 550 и 600 мл
A19: • | B19: Гарантия 3 года
A21: Семантика
A22: Группа | B22: Фраза | C22: Частотность
A23: Тип + покупка | B23: вертикальный моющий пылесос купить | C23: 10486
A24: Тип + покупка | B24: моющий вертикальный пылесос для дома купить | C24: 1724
A25: Тип + покупка | B25: вертикальный моющий пылесос цена | C25: 1567
A26: Тип + покупка | B26: недорогие вертикальные моющие пылесосы | C26: 1215
A27: Тип + покупка | B27: бюджетный вертикальный моющий пылесос | C27: 1000
A28: Тип + покупка | B28: моющие беспроводные вертикальные пылесосы цены | C28: 547
A29: Самоочистка и база | B29: вертикальные моющие пылесосы с сушкой | C29: 2192
A30: Самоочистка и база | B30: моющий пылесос вертикальный станция | C30: 2117
A31: Самоочистка и база | B31: моющий пылесос вертикальный со станцией | C31: 1104
A32: Беспроводной | B32: беспроводные моющие пылесосы для дома вертикальные | C32: 9882
A33: Назначение | B33: вертикальный моющий пылесос для дома | C33: 23105
A34: Назначение | B34: вертикальный моющий пылесос сухая | C34: 9907
... A47: Тип | B47: вертикальный моющий пылесос с подсветкой | C47: 548
A48: Модель | B48: aqvion pro
A49: Модель | B49: пылесос aqvion
A50: Модель | B50: aqvion pro купить
A52: Минус-слова товара (+ общие и конкуренты — лист «Минус-слова»)
A53: Товар | B53: робот, ручной, автомобильный, машины, щетка, валик, фильтр, аккумулятор, средство, сменные, запасные
A54: Конкуренты | B54: dyson, дайсон, dreame, дриме, дрими, дреаме, dream, roborock, роборок, tineco, тинеко, xiaomi, сяоми, ксиоми, karcher, керхер, tefal, тефаль, polaris, поларис, kitfort, китфорт, redmond, редмонд, philips, филипс, bosch, бош, samsung, самсунг, lg, vitek, витек, thomas, томас, deerma, jimmy, hwnd, atvel, атвел, puppyoo, viomi, midea, electrolux, haier, x clean, f16, ultimate, neatsvor, karingbee, chovery, ксиаоми, house up
A56: Объявления — Поиск
...

Sheet Cleneo Pro
A1: Компактный моющий пылесос Cleneo Pro
A2: Страница | B2: https://luxhomme.store/products/kompaktnyj-moyushhij-pylesos-cleneo-pro
A3: SKU | B3: VACCLCOMPACT
A4: Цена, ₽ | B4: 16990
A5: С промокодом, ₽ | B5: =ROUND(B4*(1-Товары!$B$1),0)
A6: Промокод | B6: DIRECT20
A7: Категория | B7: Пылесосы
A9: УТП (факты из карточки)
A10: • | B10: Для дома и автомобиля: полы, ковры, мягкая мебель, салон
A11: • | B11: Пар 20–26 г/мин или распыление воды
A12: • | B12: Всасывание от 15 000 Па, 1400 Вт
A13: • | B13: Нагрев пара за 30 секунд
A14: • | B14: Баки: чистая вода 1,8 л, грязная 1,2 л
A15: • | B15: 11 насадок + 2 адаптера
A16: • | B16: Сухая и влажная уборка, 4 режима
A17: • | B17: Кабель 4,5 м, радиус 6,5 м
A18: • | B18: Гарантия 3 года
A20: Семантика
A21: Группа | B21: Фраза
A22: Тип + покупка | B22: моющий пылесос купить
A23: Тип + покупка | B23: моющий пылесос для дома купить
A24: Тип + покупка | B24: компактный моющий пылесос
A25: Тип + покупка | B25: моющий пылесос цена
A26: Химчистка мебели | B26: моющий пылесос для мебели
A27: Химчистка мебели | B27: моющий пылесос для химчистки мебели
A28: Химчистка мебели | B28: пылесос для химчистки дивана
A29: Химчистка мебели | B29: пылесос для химчистки мягкой мебели
A30: Химчистка мебели | B30: моющий пылесос для дивана
A31: Химчистка мебели | B31: пылесос для химчистки купить
A32: Авто | B32: моющий пылесос для автомобиля
... A42: Модель | B42: cleneo pro купить
A44: Минус-слова товара (+ общие и конкуренты — лист «Минус-слова»)
A45: Товар | B45: вертикальный, робот, беспроводной, аккумуляторный, ручной, средство, шампунь, сменные
A46: Конкуренты | B46: dyson, дайсон, dreame, дриме, дрими, дреаме, dream, roborock, роборок, tineco, тинеко, xiaomi, сяоми, ксиоми, karcher, керхер, tefal, тефаль, polaris, поларис, kitfort, китфорт, redmond, редмонд, philips, филипс, bosch, бош, samsung, самсунг, lg, vitek, витек, thomas, томас, deerma, jimmy, hwnd, atvel, атвел, puppyoo, viomi, midea, electrolux, haier, x clean, f16, ultimate, neatsvor, karingbee, chovery, ксиаоми, house up
A48: Объявления — Поиск
A49: № | B49: Заголовок 1 | C49: ≤56 | D49: Заголовок 2 | E49: ≤30 | F49: Текст | G49: ≤81 | H49: Отображаемая ссылка (≤20)
A50: 1 | B50: Моющий пылесос Cleneo Pro для дома и авто со скидкой 20% | C50: =LEN(B50) | D50: Пар и распыление | E50: =LEN(D50) | F50: Полы, ковры, мебель и салон авто. 11 насадок, баки 1,8 и 1,2 л. Промокод DIRECT20 | G50: =LEN(F50) | H50: Cleneo-Pro
A51: 2 | B51: Пылесос для химчистки мебели и ковров с паром | C51: =LEN(B51) | D51: Скидка 20% на сайте | E51: =LEN(D51) | F51: Cleneo Pro: всасывание от 15 000 Па, пар 20–26 г/мин, нагрев 30 секунд. | G51: =LEN(F51) | H51: Cleneo-Pro
A52: 3 | B52: Купить моющий пылесос Cleneo Pro за 13 592 ₽ | C52: =LEN(B52) | D52: Промокод DIRECT20 | E52: =LEN(D52) | F52: Сухая и влажная уборка, 4 режима, кабель 4,5 м. Гарантия 3 года. | G52: =LEN(F52) | H52: Cleneo-Pro
A53: Ссылка (UTM) | B53: https://luxhomme.store/products/kompaktnyj-moyushhij-pylesos-cleneo-pro?utm_source=yandex&utm_medium=cpc&utm_campaign=lux_search_pylesosy_{campaign_id}&utm_content=cleneo-pro_{ad_id}_{source_type}&utm_term={keyword}
...

Sheet Aerlyn
A1: Вертикальный сухой пылесос Aerlyn
A2: Страница | B2: https://luxhomme.store/products/vertikalnyj-suhoj-pylesos-aerlyn
A3: SKU | B3: VACCLDRY
A4: Цена, ₽ | B4: 15990
A5: С промокодом, ₽ | B5: =ROUND(B4*(1-Товары!$B$1),0)
A6: Промокод | B6: DIRECT20
A7: Категория | B7: Пылесосы
A9: УТП (факты из карточки)
A10: • | B10: 2 в 1: вертикальный и ручной
A11: • | B11: Всасывание до 35 кПа, 420 Вт
A12: • | B12: Аккумулятор 2200 мАч, до 60 минут
A13: • | B13: Режимы ECO / FLOOR / CARPET / TURBO + авто
A14: • | B14: Турбощётка, 8 насадок
A15: • | B15: HEPA-фильтр, бак 330 мл
A16: • | B16: Вес 2,35 кг, поворот 180°
A17: • | B17: Настенное крепление для зарядки
A18: • | B18: Гарантия 3 года
A20: Семантика
A21: Группа | B21: Фраза
A22: Тип + покупка | B22: вертикальный пылесос купить
A23: Тип + покупка | B23: беспроводной пылесос купить
A24: Тип + покупка | B24: беспроводной пылесос для дома купить
A25: Тип + покупка | B25: вертикальный пылесос цена
A26: Тип + покупка | B26: аккумуляторный пылесос вертикальный
A27: Назначение | B27: вертикальный пылесос для дома
A28: Назначение | B28: беспроводной вертикальный пылесос
A29: Назначение | B29: вертикальный пылесос для ковров
A30: Назначение | B30: беспроводной пылесос для квартиры
A31: Характеристики | B31: вертикальный пылесос 2 в 1
A32: Характеристики | B32: пылесос вертикальный ручной 2 в 1
... A39: Модель | B39: aerlyn купить
A41: Минус-слова товара (+ общие и конкуренты — лист «Минус-слова»)
A42: Товар | B42: моющий, моет, влажной, влажная, робот, автомобильный, машины, строительный, садовый, щетка, сменные
A43: Конкуренты | B43: dyson, дайсон, dreame, дриме, дрими, дреаме, dream, roborock, роборок, tineco, тинеко, xiaomi, сяоми, ксиоми, karcher, керхер, tefal, тефаль, polaris, поларис, kitfort, китфорт, redmond, редмонд, philips, филипс, bosch, бош, samsung, самсунг, lg, vitek, витек, thomas, томас, deerma, jimmy, hwnd, atvel, атвел, puppyoo, viomi, midea, electrolux, haier, x clean, f16, ultimate, neatsvor, karingbee, chovery, ксиаоми, house up
A45: Объявления — Поиск
A46: № | B46: Заголовок 1 | C46: ≤56 | D46: Заголовок 2 | E46: ≤30 | F46: Текст | G46: ≤81 | H46: Отображаемая ссылка (≤20)
A47: 1 | B47: Беспроводной пылесос Aerlyn 2 в 1 — до 35 кПа | C47: =LEN(B47) | D47: Скидка 20% на сайте | E47: =LEN(D47) | F47: До 60 минут работы, HEPA-фильтр, турбощётка, 8 насадок. Промокод DIRECT20. | G47: =LEN(F47) | H47: Aerlyn
A48: 2 | B48: Вертикальный беспроводной пылесос с HEPA-фильтром | C48: =LEN(B48) | D48: Скидка 20% по промокоду | E48: =LEN(D48) | F48: Aerlyn: режимы ECO, FLOOR, CARPET, TURBO и авто. Гарантия 3 года. | G48: =LEN(F48) | H48: Aerlyn
A49: 3 | B49: Купить вертикальный пылесос Aerlyn за 12 792 ₽ | C49: =LEN(B49) | D49: Промокод DIRECT20 | E49: =LEN(D49) | F49: 420 Вт, бак 330 мл, вес 2,35 кг, настенное крепление для зарядки. | G49: =LEN(F49) | H49: Aerlyn
A50: Ссылка (UTM) | B50: https://luxhomme.store/products/vertikalnyj-suhoj-pylesos-aerlyn?utm_source=yandex&utm_medium=cpc&utm_campaign=lux_search_pylesosy_{campaign_id}&utm_content=aerlyn_{ad_id}_{source_type}&utm_term={keyword}
...

Sheet EcoSteam Pro
A1: Паровая швабра Luxhommè EcoSteam Pro
A2: Страница | B2: https://luxhomme.store/products/ecosteam-pro
A3: SKU | B3: SHVPAREKCHB2
A4: Цена, ₽ | B4: 5990
A5: С промокодом, ₽ | B5: =ROUND(B4*(1-Товары!$B$1),0)
A6: Промокод | B6: DIRECT20
A7: Категория | B7: Паровые швабры
A9: УТП (факты из карточки)
A10: • | B10: Нагрев за 30 секунд
A11: • | B11: 1400 Вт, пар до 120 °C, подача 18–20 / 25–30 г/мин
A12: • | B12: 22 насадки в комплекте: окна, швы, металл, углы
A13: • | B13: Освежает полы и разглаживает одежду
A14: • | B14: Поворот головки 270°, вес 1,83 кг
A15: • | B15: Бак 400 мл, шнур 5 м, 25 минут непрерывной работы
A16: • | B16: Гарантия 12 месяцев
A18: Семантика
A19: Группа | B19: Фраза
A20: Тип + покупка | B20: паровая швабра купить
A21: Тип + покупка | B21: купить паровую швабру для дома
A22: Тип + покупка | B22: паровая швабра цена
A23: Тип + покупка | B23: паровая швабра недорого
A24: Тип + покупка | B24: паровая швабра интернет магазин
A25: Тип + покупка | B25: швабра с паром купить
A26: Назначение | B26: паровая швабра для дома
A27: Назначение | B27: паровая швабра для пола
A28: Назначение | B28: паровая швабра для плитки
A29: Назначение | B29: паровая швабра для уборки квартиры
A30: Назначение | B30: швабра с паром для пола
... A39: Модель | B39: швабра ecosteam pro купить
A41: Минус-слова товара (+ общие и конкуренты — лист «Минус-слова»)
A42: Товар | B42: ручная, отжим, отжимом, тряпка, веревочная, spin, сменные, запасные, салфетки, щетка
A43: Конкуренты | B43: karcher, керхер, tefal, тефаль, kitfort, китфорт, polaris, поларис, bissell, биссел, black decker, vileda, виледа, leifheit, vax, endever, clatronic, kelli, bort, redmond, редмонд, philips, филипс
A45: Объявления — Поиск
A46: № | B46: Заголовок 1 | C46: ≤56 | D46: Заголовок 2 | E46: ≤30 | F46: Текст | G46: ≤81 | H46: Отображаемая ссылка (≤20)
A47: 1 | B47: Паровая швабра EcoSteam Pro — 22 насадки | C47: =LEN(B47) | D47: Скидка 20% по промокоду | E47: =LEN(D47) | F47: Нагрев за 30 секунд, пар до 120 °C, бак 400 мл, шнур 5 м. Промокод DIRECT20. | G47: =LEN(F47) | H47: EcoSteam-Pro
A48: 2 | B48: Паровая швабра для дома — нагрев за 30 секунд | C48: =LEN(B48) | D48: Скидка 20% на сайте | E48: =LEN(D48) | F48: EcoSteam Pro: 1400 Вт, 22 насадки, поворот 270°. С промокодом — 4 792 ₽. | G48: =LEN(F48) | H48: EcoSteam-Pro
A49: 3 | B49: Купить паровую швабру EcoSteam Pro за 4 792 ₽ | C49: =LEN(B49) | D49: Промокод DIRECT20 | E49: =LEN(D49) | F49: Пар до 120 °C, 22 насадки, вес 1,83 кг. Гарантия 12 месяцев. | G49: =LEN(F49) | H49: EcoSteam-Pro
A50: Ссылка (UTM) | B50: https://luxhomme.store/products/ecosteam-pro?utm_source=yandex&utm_medium=cpc&utm_campaign=lux_search_shvabry_{campaign_id}&utm_content=ecosteam-pro_{ad_id}_{source_type}&utm_term={keyword}
A52: Быстрые ссылки
A53: Название | B53: Описание | C53: ≤60 | D53: Ссылка (UTM) | H53: Название ≤30
...

Sheet AirSteam Pro
A1: Паровая швабра Luxhommè AirSteam Pro
A2: Страница | B2: https://luxhomme.store/products/steamly-pro
A3: SKU | B3: SHVPAR3D
A4: Цена, ₽ | B4: 10990
A5: С промокодом, ₽ | B5: =ROUND(B4*(1-Товары!$B$1),0)
A6: Промокод | B6: DIRECT20
A7: Категория | B7: Паровые швабры
A9: УТП (факты из карточки)
A10: • | B10: 1800 Вт, пар до 150 °C
A11: • | B11: 3 режима пара, 15–48 г/мин
A12: • | B12: Нагрев 25–30 секунд
A13: • | B13: 25 насадок в комплекте
A14: • | B14: Отпаривание одежды
A15: • | B15: Аромакапсулы, автоотключение
A16: • | B16: Бак 450 мл
A17: • | B17: Гарантия 3 года
A19: Семантика
A20: Группа | B20: Фраза
A21: Тип + покупка | B21: паровая швабра купить
A22: Тип + покупка | B22: купить паровую швабру
A23: Тип + покупка | B23: паровая швабра цена
A24: Тип + покупка | B24: паровая швабра для дома купить
A25: С отпаривателем | B25: паровая швабра с отпаривателем
A26: С отпаривателем | B26: паровая швабра отпариватель для одежды
A27: С отпаривателем | B27: швабра отпариватель
A28: С отпаривателем | B28: паровая швабра и отпариватель
A29: Характеристики | B29: мощная паровая швабра
A30: Характеристики | B30: паровая швабра 1800 вт
A31: Характеристики | B31: паровая швабра с регулировкой пара
... A40: Модель | B40: швабра airsteam pro купить
A42: Минус-слова товара (+ общие и конкуренты — лист «Минус-слова»)
A43: Товар | B43: ручная, отжим, отжимом, тряпка, веревочная, spin, сменные, запасные, салфетки, щетка, вертикальный
A44: Конкуренты | B44: karcher, керхер, tefal, тефаль, kitfort, китфорт, polaris, поларис, bissell, биссел, black decker, vileda, виледа, leifheit, vax, endever, clatronic, kelli, bort, redmond, редмонд, philips, филипс
A46: Объявления — Поиск
A47: № | B47: Заголовок 1 | C47: ≤56 | D47: Заголовок 2 | E47: ≤30 | F47: Текст | G47: ≤81 | H47: Отображаемая ссылка (≤20)
A48: 1 | B48: Паровая швабра AirSteam Pro — пар до 150 °C | C48: =LEN(B48) | D48: Скидка 20% на сайте | E48: =LEN(D48) | F48: 1800 Вт, 3 режима пара, 25 насадок, отпаривание одежды. Промокод DIRECT20. | G48: =LEN(F48) | H48: AirSteam-Pro
A49: 2 | B49: Паровая швабра с отпариванием одежды | C49: =LEN(B49) | D49: Скидка 20% по промокоду | E49: =LEN(D49) | F49: AirSteam Pro: нагрев 25–30 с, бак 450 мл, автоотключение. Гарантия 3 года. | G49: =LEN(F49) | H49: AirSteam-Pro
A50: 3 | B50: Купить паровую швабру AirSteam Pro за 8 792 ₽ | C50: =LEN(B50) | D50: Промокод DIRECT20 | E50: =LEN(D50) | F50: До 48 г/мин пара, 3 режима, поддержка аромакапсул. Гарантия 3 года. | G50: =LEN(F50) | H50: AirSteam-Pro
A51: Ссылка (UTM) | B51: https://luxhomme.store/products/steamly-pro?utm_source=yandex&utm_medium=cpc&utm_campaign=lux_search_shvabry_{campaign_id}&utm_content=airsteam-pro_{ad_id}_{source_type}&utm_term={keyword}
A53: Быстрые ссылки
...

Sheet SC-100 Max
A1: Паровая швабра Luxhommè SC-100 Max
A2: Страница | B2: https://luxhomme.store/products/sc-100
A3: SKU | B3: SHVPAR7V1CH
A4: Цена, ₽ | B4: 7990
A5: С промокодом, ₽ | B5: =ROUND(B4*(1-Товары!$B$1),0)
A6: Промокод | B6: DIRECT20
A7: Категория | B7: Паровые швабры
A9: УТП (факты из карточки)
A10: • | B10: 1500 Вт, пар до 150 °C
A11: • | B11: Давление 4,5 бар
A12: • | B12: 2 режима подачи пара: 12–16 / 25–32 г/мин
A13: • | B13: Нагрев 30 секунд
A14: • | B14: 9 насадок + 3 микрофибры
A15: • | B15: Бак 360 мл, шнур 5 м
A16: • | B16: Гарантия 3 года
A18: Семантика
A19: Группа | B19: Фраза
A20: Тип + покупка | B20: паровая швабра купить
A21: Тип + покупка | B21: купить паровую швабру для пола
A22: Тип + покупка | B22: паровая швабра цена
A23: Тип + покупка | B23: швабра с паром купить
A24: Назначение | B24: паровая швабра для дома
A25: Назначение | B25: паровая швабра для пола
A26: Назначение | B26: швабра с паром для пола
A27: Назначение | B27: паровой очиститель для пола
A28: Характеристики | B28: паровая швабра с давлением
A29: Характеристики | B29: паровая швабра 1500 вт
A30: Характеристики | B30: паровая швабра с микрофиброй
... A36: Модель | B36: швабра sc100
A38: Минус-слова товара (+ общие и конкуренты — лист «Минус-слова»)
A39: Товар | B39: ручная, отжим, отжимом, тряпка, веревочная, spin, сменные, запасные, салфетки, щетка
A40: Конкуренты | B40: karcher, керхер, tefal, тефаль, kitfort, китфорт, polaris, поларис, bissell, биссел, black decker, vileda, виледа, leifheit, vax, endever, clatronic, kelli, bort, redmond, редмонд, philips, филипс
A42: Объявления — Поиск
A43: № | B43: Заголовок 1 | C43: ≤56 | D43: Заголовок 2 | E43: ≤30 | F43: Текст | G43: ≤81 | H43: Отображаемая ссылка (≤20)
A44: 1 | B44: Паровая швабра SC-100 Max — давление 4,5 бар | C44: =LEN(B44) | D44: Скидка 20% на сайте | E44: =LEN(D44) | F44: 1500 Вт, пар до 150 °C, 2 режима подачи пара, 9 насадок. Промокод DIRECT20. | G44: =LEN(F44) | H44: SC-100-Max
A45: 2 | B45: Паровая швабра с 9 насадками и микрофиброй | C45: =LEN(B45) | D45: Скидка 20% по промокоду | E45: =LEN(D45) | F45: SC-100 Max: нагрев 30 секунд, бак 360 мл, шнур 5 м. Гарантия 3 года. | G45: =LEN(F45) | H45: SC-100-Max
A46: 3 | B46: Купить паровую швабру SC-100 Max за 6 392 ₽ | C46: =LEN(B46) | D46: Промокод DIRECT20 | E46: =LEN(D46) | F46: До 32 г/мин пара и до 150 °C. 9 насадок и 3 микрофибры в комплекте. | G46: =LEN(F46) | H46: SC-100-Max
A47: Ссылка (UTM) | B47: https://luxhomme.store/products/sc-100?utm_source=yandex&utm_medium=cpc&utm_campaign=lux_search_shvabry_{campaign_id}&utm_content=sc-100-max_{ad_id}_{source_type}&utm_term={keyword}
A49: Быстрые ссылки
A50: Название | B50: Описание | C50: ≤60 | D50: Ссылка (UTM) | H50: Название ≤30
...

Sheet CoffeeMaker Classic
A1: Кофемашина Luxhommè CoffeeMaker Classic
A2: Страница | B2: https://luxhomme.store/products/coffee
A3: SKU | B3: COFMASHCAP4V1
A4: Цена, ₽ | B4: 9990
A5: С промокодом, ₽ | B5: =ROUND(B4*(1-Товары!$B$1),0)
A6: Промокод | B6: DIRECT20
A7: Категория | B7: Кофемашины
A9: УТП (факты из карточки)
A10: • | B10: Капсулы формата Nespresso, чалды и молотый кофе
A11: • | B11: Помпа 19 бар, 1450 Вт
A12: • | B12: Капучинатор: латте, капучино, эспрессо
A13: • | B13: Горячие и холодные напитки
A14: • | B14: Тёплый кофе через 20 секунд, шум 60–65 дБ
A15: • | B15: Компактная: ширина 11,7 см
A16: • | B16: Бак 0,6 л
A17: • | B17: Гарантия 3 года
A19: Семантика
A20: Группа | B20: Фраза
A21: Тип + покупка | B21: капсульная кофемашина купить
A22: Тип + покупка | B22: кофемашина капсульная для дома
A23: Тип + покупка | B23: кофемашина для дома купить
A24: Тип + покупка | B24: кофеварка капсульная
A25: Тип + покупка | B25: кофемашина недорого
A26: Форматы кофе | B26: кофемашина для капсул nespresso
A27: Форматы кофе | B27: кофемашина под капсулы неспрессо
A28: Форматы кофе | B28: кофемашина для чалд
A29: Форматы кофе | B29: кофемашина для молотого кофе и капсул
A30: Форматы кофе | B30: кофемашина капсулы и молотый
A31: Характеристики | B31: компактная кофемашина для дома
... A37: Модель | B37: кофемашина coffeemaker
A39: Минус-слова товара (+ общие и конкуренты — лист «Минус-слова»)
A40: Товар | B40: зерновая, зерно, кофемолка, рожковая, капельная, турка, гейзерная, декальцинация, чистка, таблетки, многоразовые
A41: Конкуренты | B41: delonghi, делонги, philips, филипс, saeco, krups, крупс, jura, nivona, melitta, bosch, siemens, polaris, поларис, kitfort, китфорт, redmond, редмонд, garlyn, гарлин, vitek, xiaomi, smeg, gaggia, sage, breville, oursson, starwind, dauken
A43: Объявления — Поиск
A44: № | B44: Заголовок 1 | C44: ≤56 | D44: Заголовок 2 | E44: ≤30 | F44: Текст | G44: ≤81 | H44: Отображаемая ссылка (≤20)
A45: 1 | B45: Кофемашина: капсулы Nespresso, чалды и молотый | C45: =LEN(B45) | D45: Скидка 20% на сайте | E45: =LEN(D45) | F45: CoffeeMaker Classic: 19 бар, капучинатор, горячий и холодный кофе. Код DIRECT20 | G45: =LEN(F45) | H45: CoffeeMaker-Classic
A46: 2 | B46: Компактная капсульная кофемашина — ширина 11,7 см | C46: =LEN(B46) | D46: Скидка 20% по промокоду | E46: =LEN(D46) | F46: Кофе через 20 секунд, тихая работа 60–65 дБ, помпа 19 бар. Гарантия 3 года. | G46: =LEN(F46) | H46: CoffeeMaker-Classic
A47: 3 | B47: Купить кофемашину CoffeeMaker Classic за 7 992 ₽ | C47: =LEN(B47) | D47: Промокод DIRECT20 | E47: =LEN(D47) | F47: Эспрессо, латте и капучино дома. Капсулы формата Nespresso, чалды, молотый. | G47: =LEN(F47) | H47: CoffeeMaker-Classic
A48: Ссылка (UTM) | B48: https://luxhomme.store/products/coffee?utm_source=yandex&utm_medium=cpc&utm_campaign=lux_search_kofe_{campaign_id}&utm_content=coffeemaker-classic_{ad_id}_{source_type}&utm_term={keyword}
A50: Быстрые ссылки
...

Sheet Caffio Professional
A1: Кофемашина рожковая Luxhommè Caffio Professional
A2: Страница | B2: https://luxhomme.store/products/caffio-professional
A3: SKU | B3: COFMASHROZH
A4: Цена, ₽ | B4: 17990
A5: С промокодом, ₽ | B5: =ROUND(B4*(1-Товары!$B$1),0)
A6: Промокод | B6: DIRECT20
A7: Категория | B7: Кофемашины
A9: УТП (факты из карточки)
A10: • | B10: Рожковая 4 в 1: молотый, капсулы Nespresso и Dolce Gusto, чалды ESE
A11: • | B11: Итальянская помпа ULKA 20 бар
A12: • | B12: Thermoblock — нагрев от 10 секунд
A13: • | B13: Автоматический капучинатор с регулировкой пены
A14: • | B14: Горячий и холодный кофе
A15: • | B15: Бак 1,5 л, молочник 500 мл
A16: • | B16: Гарантия 3 года
A18: Семантика
A19: Группа | B19: Фраза
A20: Тип + покупка | B20: рожковая кофемашина купить
A21: Тип + покупка | B21: рожковая кофемашина для дома
A22: Тип + покупка | B22: кофемашина рожкового типа
A23: Тип + покупка | B23: кофемашина для дома с капучинатором
A24: Характеристики | B24: рожковая кофемашина с капучинатором
A25: Характеристики | B25: кофемашина с автоматическим капучинатором
A26: Характеристики | B26: кофеварка рожковая с капучинатором
A27: Характеристики | B27: кофемашина 20 бар
A28: Характеристики | B28: кофемашина с молочником
A29: Характеристики | B29: кофемашина для холодного кофе
A30: Характеристики | B30: кофемашина 4 в 1
... A35: Модель | B35: кофемашина caffio
A37: Минус-слова товара (+ общие и конкуренты — лист «Минус-слова»)
A38: Товар | B38: зерновая, зерно, кофемолка, капельная, турка, гейзерная, декальцинация, чистка, таблетки, многоразовые
A39: Конкуренты | B39: delonghi, делонги, philips, филипс, saeco, krups, крупс, jura, nivona, melitta, bosch, siemens, polaris, поларис, kitfort, китфорт, redmond, редмонд, garlyn, гарлин, vitek, xiaomi, smeg, gaggia, sage, breville, oursson, starwind, dauken
A41: Объявления — Поиск
A42: № | B42: Заголовок 1 | C42: ≤56 | D42: Заголовок 2 | E42: ≤30 | F42: Текст | G42: ≤81 | H42: Отображаемая ссылка (≤20)
A43: 1 | B43: Рожковая кофемашина Caffio Professional со скидкой 20% | C43: =LEN(B43) | D43: Автокапучинатор | E43: =LEN(D43) | F43: Помпа ULKA 20 бар, Thermoblock, 4 формата кофе. Промокод DIRECT20 на сайте. | G43: =LEN(F43) | H43: Caffio-Professional
A44: 2 | B44: Кофемашина 4 в 1: молотый, капсулы и чалды ESE | C44: =LEN(B44) | D44: Скидка 20% на сайте | E44: =LEN(D44) | F44: Caffio Professional: регулировка пены, горячий и холодный кофе. Гарантия 3 года. | G44: =LEN(F44) | H44: Caffio-Professional
A45: 3 | B45: Купить рожковую кофемашину Caffio за 14 392 ₽ | C45: =LEN(B45) | D45: Промокод DIRECT20 | E45: =LEN(D45) | F45: Бак 1,5 л и молочник 500 мл, нагрев Thermoblock от 10 секунд. | G45: =LEN(F45) | H45: Caffio-Professional
A46: Ссылка (UTM) | B46: https://luxhomme.store/products/caffio-professional?utm_source=yandex&utm_medium=cpc&utm_campaign=lux_search_kofe_{campaign_id}&utm_content=caffio-professional_{ad_id}_{source_type}&utm_term={keyword}
A48: Быстрые ссылки
A49: Название | B49: Описание | C49: ≤60 | D49: Ссылка (UTM) | H49: Название ≤30
...

Sheet CremaX
A1: Кофемашина автоматическая зерновая с капучинатором и кофемолкой CremaX
A2: Страница | B2: https://luxhomme.store/products/cremax
A3: SKU | B3: COFMASHPOMOL
A4: Цена, ₽ | B4: 47990
A5: С промокодом, ₽ | B5: =ROUND(B4*(1-Товары!$B$1),0)
A6: Промокод | B6: DIRECT20
A7: Категория | B7: Кофемашины
A9: УТП (факты из карточки)
A10: • | B10: 5 в 1: зерно, молотый, Nespresso, Dolce Gusto, чалды ESE
A11: • | B11: Встроенная кофемолка, 20 степеней помола, бункер 120 г
A12: • | B12: Помпа ULKA 20 бар, Thermoblock, нагрев от 25 секунд
A13: • | B13: Предсмачивание
A14: • | B14: 10 программ, горячий и холодный кофе
A15: • | B15: Автоматический съёмный капучинатор, регулировка пены
A16: • | B16: Бак 2 л, шум 50 дБ
A17: • | B17: Гарантия 3 года
A19: Семантика
A20: Группа | B20: Фраза
A21: Тип + покупка | B21: кофемашина с кофемолкой купить
A22: Тип + покупка | B22: кофемашина с кофемолкой для дома
A23: Тип + покупка | B23: кофемашина зерновая для дома купить
A24: Тип + покупка | B24: автоматическая кофемашина с капучинатором для дома
A25: Характеристики | B25: кофемашина со встроенной кофемолкой
A26: Характеристики | B26: рожковая кофемашина с кофемолкой
A27: Характеристики | B27: кофемашина зерновая с капучинатором
A28: Характеристики | B28: кофемашина 20 бар с кофемолкой
A29: Характеристики | B29: кофемашина с предсмачиванием
A30: Характеристики | B30: кофемашина для холодного кофе с кофемолкой
A31: Форматы кофе | B31: кофемашина для зерна и капсул
... A36: Модель | B36: crema x кофемашина
A38: Минус-слова товара (+ общие и конкуренты — лист «Минус-слова»)
A39: Товар | B39: капельная, турка, гейзерная, ручная, декальцинация, чистка, таблетки, многоразовые
A40: Конкуренты | B40: delonghi, делонги, philips, филипс, saeco, krups, крупс, jura, nivona, melitta, bosch, siemens, polaris, поларис, kitfort, китфорт, redmond, редмонд, garlyn, гарлин, vitek, xiaomi, smeg, gaggia, sage, breville, oursson, starwind, dauken
A42: Объявления — Поиск
A43: № | B43: Заголовок 1 | C43: ≤56 | D43: Заголовок 2 | E43: ≤30 | F43: Текст | G43: ≤81 | H43: Отображаемая ссылка (≤20)
A44: 1 | B44: Кофемашина с кофемолкой CremaX — скидка 20% | C44: =LEN(B44) | D44: Промокод DIRECT20 | E44: =LEN(D44) | F44: 20 степеней помола, помпа ULKA 20 бар, автокапучинатор, 10 программ. | G44: =LEN(F44) | H44: CremaX
A45: 2 | B45: Кофемашина 5 в 1: зерно, молотый, капсулы, ESE | C45: =LEN(B45) | D45: Скидка 20% на сайте | E45: =LEN(D45) | F45: CremaX: предсмачивание, холодный кофе, бак 2 л, нагрев от 25 с. Гарантия 3 года. | G45: =LEN(F45) | H45: CremaX
A46: 3 | B46: Купить кофемашину CremaX за 38 392 ₽ | C46: =LEN(B46) | D46: Промокод DIRECT20 | E46: =LEN(D46) | F46: Встроенная кофемолка, бункер 120 г. Горячий и холодный кофе, шум 50 дБ. | G46: =LEN(F46) | H46: CremaX
A47: Ссылка (UTM) | B47: https://luxhomme.store/products/cremax?utm_source=yandex&utm_medium=cpc&utm_campaign=lux_search_kofe_{campaign_id}&utm_content=cremax_{ad_id}_{source_type}&utm_term={keyword}
A49: Быстрые ссылки
...

Sheet AirChef
A1: Аэрогриль Luxhommè AirChef
A2: Страница | B2: https://luxhomme.store/products/airgrill
A3: SKU | B3: AEROGRIL55L2
A4: Цена, ₽ | B4: 5990
A5: С промокодом, ₽ | B5: =ROUND(B4*(1-Товары!$B$1),0)
A6: Промокод | B6: DIRECT20
A7: Категория | B7: Аэрогрили
A9: УТП (факты из карточки)
A10: • | B10: Чаша 5,5 л — на 2–4 человека
A11: • | B11: 1500 Вт, 35–200 °C
A12: • | B12: 12 программ
A13: • | B13: Смотровое окно с подсветкой
A14: • | B14: Режим сушки
A15: • | B15: Гарантия 3 года
A17: Семантика
A18: Группа | B18: Фраза
A19: Тип + покупка | B19: аэрогриль купить
A20: Тип + покупка | B20: аэрогриль для дома купить
A21: Тип + покупка | B21: аэрогриль цена
A22: Тип + покупка | B22: аэрогриль недорого
A23: Тип + покупка | B23: купить аэрогриль с окном
A24: Характеристики | B24: аэрогриль с окошком
A25: Характеристики | B25: аэрогриль со смотровым окном
A26: Характеристики | B26: аэрогриль 5 литров
A27: Характеристики | B27: аэрогриль 5.5 л
A28: Характеристики | B28: аэрогриль с функцией сушки
A29: Характеристики | B29: аэрогриль 1500 вт
... A35: Модель | B35: аэрогриль airchef
A37: Минус-слова товара (+ общие и конкуренты — лист «Минус-слова»)
A38: Товар | B38: рецепт, рецепты, рецептами, приготовить, готовить, сколько, минут, книга, пергамент, бумага, форма, решетка, подставка, две, двумя, двойной, двухкамерный, dual
A39: Конкуренты | B39: tefal, тефаль, philips, филипс, ninja, ниндзя, cosori, косори, xiaomi, redmond, редмонд, polaris, поларис, kitfort, китфорт, moulinex, мулинекс, instant, hotter, gfgril, oberhof, garlyn, гарлин, proficook, vitek, dexp, dauken
A41: Объявления — Поиск
A42: № | B42: Заголовок 1 | C42: ≤56 | D42: Заголовок 2 | E42: ≤30 | F42: Текст | G42: ≤81 | H42: Отображаемая ссылка (≤20)
A43: 1 | B43: Аэрогриль AirChef 5,5 л с окном — скидка 20% | C43: =LEN(B43) | D43: Промокод DIRECT20 | E43: =LEN(D43) | F43: 12 программ, 35–200 °C, подсветка камеры, режим сушки. Для 2–4 человек. | G43: =LEN(F43) | H43: AirChef
A44: 2 | B44: Аэрогриль для дома: 12 программ и сушка | C44: =LEN(B44) | D44: Скидка 20% на сайте | E44: =LEN(D44) | F44: AirChef: 1500 Вт, чаша 5,5 л, смотровое окно. Гарантия 3 года. | G44: =LEN(F44) | H44: AirChef
A45: 3 | B45: Купить аэрогриль AirChef за 4 792 ₽ | C45: =LEN(B45) | D45: Скидка 20% по промокоду | E45: =LEN(D45) | F45: Чаша 5,5 литра, окно с подсветкой, температура от 35 до 200 °C. | G45: =LEN(F45) | H45: AirChef
A46: Ссылка (UTM) | B46: https://luxhomme.store/products/airgrill?utm_source=yandex&utm_medium=cpc&utm_campaign=lux_search_aerogrili_{campaign_id}&utm_content=airchef_{ad_id}_{source_type}&utm_term={keyword}
A48: Быстрые ссылки
A49: Название | B49: Описание | C49: ≤60 | D49: Ссылка (UTM) | H49: Название ≤30
A50: Каталог техники | B50: Пылесосы, швабры, кофемашины, аэрогрили | C50: =LEN(B50) | D50: https://luxhomme.store/catalog?utm_source=yandex&utm_medium=cpc&utm_campaign=lux_search_aerogrili_{campaign_id}&utm_content=airchef_sitelink_{ad_id}_{source_type}&utm_term={keyword} | H50: =LEN(A50)
...

Sheet AirChef Dual Pro
A1: Аэрогриль Luxhommè AirChef Dual Pro (2 чаши)
A2: Страница | B2: https://luxhomme.store/products/airgrill-dual-pro
A3: SKU | B3: AEROGRIL2CHASHI
A4: Цена, ₽ | B4: 16990
A5: С промокодом, ₽ | B5: =ROUND(B4*(1-Товары!$B$1),0)
A6: Промокод | B6: DIRECT20
A7: Категория | B7: Аэрогрили
A9: УТП (факты из карточки)
A10: • | B10: Две независимые чаши: 7 л сверху и 5 л снизу
A11: • | B11: Горячее и гарнир одновременно, запахи не смешиваются
A12: • | B12: 3200 Вт, 30–220 °C
A13: • | B13: 18 программ, таймер до 8 часов
A14: • | B14: Синхронизация чаш
A15: • | B15: 2 смотровых окна
A16: • | B16: Можно мыть в посудомоечной машине
A17: • | B17: Гарантия 3 года
A19: Семантика
A20: Группа | B20: Фраза
A21: Тип + покупка | B21: аэрогриль с двумя чашами купить
A22: Тип + покупка | B22: аэрогриль 2 чаши купить
A23: Тип + покупка | B23: аэрогриль двойной
A24: Тип + покупка | B24: аэрогриль с двумя корзинами
A25: Характеристики | B25: аэрогриль с двумя чашами
A26: Характеристики | B26: аэрогриль большой объем
A27: Характеристики | B27: аэрогриль 7 литров
A28: Характеристики | B28: аэрогриль с синхронизацией
A29: Характеристики | B29: аэрогриль с двумя окнами
A30: Характеристики | B30: мощный аэрогриль
A31: Характеристики | B31: аэрогриль 3200 вт
... A36: Модель | B36: аэрогриль airchef dual
A38: Минус-слова товара (+ общие и конкуренты — лист «Минус-слова»)
A39: Товар | B39: рецепт, рецепты, рецептами, приготовить, готовить, сколько, минут, книга, пергамент, бумага, форма, решетка, подставка
A40: Конкуренты | B40: tefal, тефаль, philips, филипс, ninja, ниндзя, cosori, косори, xiaomi, redmond, редмонд, polaris, поларис, kitfort, китфорт, moulinex, мулинекс, instant, hotter, gfgril, oberhof, garlyn, гарлин, proficook, vitek, dexp, dauken
A42: Объявления — Поиск
A43: № | B43: Заголовок 1 | C43: ≤56 | D43: Заголовок 2 | E43: ≤30 | F43: Текст | G43: ≤81 | H43: Отображаемая ссылка (≤20)
A44: 1 | B44: Аэрогриль с двумя чашами 7 + 5 л — скидка 20% | C44: =LEN(B44) | D44: Промокод DIRECT20 | E44: =LEN(D44) | F44: AirChef Dual Pro: 3200 Вт, 18 программ, синхронизация чаш, 2 окна. | G44: =LEN(F44) | H44: AirChef-Dual-Pro
A45: 2 | B45: Аэрогриль AirChef Dual Pro: два блюда сразу | C45: =LEN(B45) | D45: Скидка 20% на сайте | E45: =LEN(D45) | F45: Чаши 7 и 5 л, 30–220 °C, таймер до 8 часов. Гарантия 3 года. | G45: =LEN(F45) | H45: AirChef-Dual-Pro
A46: 3 | B46: Купить аэрогриль на 2 чаши за 13 592 ₽ | C46: =LEN(B46) | D46: Промокод DIRECT20 | E46: =LEN(D46) | F46: Горячее и гарнир одновременно, запахи не смешиваются. 3200 Вт, 18 программ. | G46: =LEN(F46) | H46: AirChef-Dual-Pro
A47: Ссылка (UTM) | B47: https://luxhomme.store/products/airgrill-dual-pro?utm_source=yandex&utm_medium=cpc&utm_campaign=lux_search_aerogrili_{campaign_id}&utm_content=airchef-dual-pro_{ad_id}_{source_type}&utm_term={keyword}
A49: Быстрые ссылки
...

Sheet uFit 2D Standard
A1: Виброплатформа uFit 2D Standard
A2: Страница | B2: https://luxhomme.store/products/ufit-2d
A3: SKU | B3: VIPLATB
A4: Цена, ₽ | B4: 6190
A5: С промокодом, ₽ | B5: =ROUND(B4*(1-Товары!$B$1),0)
A6: Промокод | B6: DIRECT20
A7: Категория | B7: Виброплатформы
A9: УТП (факты из карточки)
A10: • | B10: 5 программ, 180 уровней скорости
A11: • | B11: Нагрузка до 150 кг
A12: • | B12: 150 Вт, сенсорный дисплей, музыка
A13: • | B13: Пульт ДУ
A14: • | B14: Эспандеры 2 шт. и фитнес-резинка в комплекте
A15: • | B15: Высота 12 см — компактно хранить
A16: • | B16: Гарантия 2 года
A18: Семантика
A19: Группа | B19: Фраза
A20: Тип + покупка | B20: виброплатформа купить
A21: Тип + покупка | B21: виброплатформа для дома купить
A22: Тип + покупка | B22: виброплатформа цена
A23: Тип + покупка | B23: виброплатформа недорого
A24: Тип + покупка | B24: вибротренажер для дома купить
A25: Назначение | B25: виброплатформа для дома
A26: Назначение | B26: виброплатформа для похудения купить
A27: Назначение | B27: виброплатформа тренажер
A28: Назначение | B28: вибротренажер для дома
A29: Характеристики | B29: виброплатформа с эспандерами
A30: Характеристики | B30: виброплатформа до 150 кг
... A34: Модель | B34: виброплатформа ufit
A36: Минус-слова товара (+ общие и конкуренты — лист «Минус-слова»)
A37: Товар | B37: ems, емс, миостимуляция, миотоки, нагрев, нагревом, подогрев, 3d, вред, противопоказания, польза, врачей, спортзал, аренда
A38: Конкуренты | B38: bradex, брадекс, torneo, торнео, clear fit, planta, планта, oxygen, hasttings, evo fitness, proxima, dfc, body sculpture, unix fit, юникс, yamaguchi, ямагучи, casada, gezatone, us medica
A40: Объявления — Поиск
A41: № | B41: Заголовок 1 | C41: ≤56 | D41: Заголовок 2 | E41: ≤30 | F41: Текст | G41: ≤81 | H41: Отображаемая ссылка (≤20)
A42: 1 | B42: Виброплатформа uFit 2D для дома — скидка 20% | C42: =LEN(B42) | D42: Промокод DIRECT20 | E42: =LEN(D42) | F42: 5 программ, 180 скоростей, нагрузка до 150 кг. Эспандеры и пульт в комплекте. | G42: =LEN(F42) | H42: uFit-2D
A43: 2 | B43: Виброплатформа с эспандерами и пультом | C43: =LEN(B43) | D43: Скидка 20% на сайте | E43: =LEN(D43) | F43: uFit 2D Standard: 150 Вт, сенсорный дисплей, музыка. Гарантия 2 года. | G43: =LEN(F43) | H43: uFit-2D
A44: 3 | B44: Купить виброплатформу uFit 2D за 4 952 ₽ | C44: =LEN(B44) | D44: Промокод DIRECT20 | E44: =LEN(D44) | F44: Тренировки дома в удобное время: 5 программ и 180 уровней скорости. | G44: =LEN(F44) | H44: uFit-2D
A45: Ссылка (UTM) | B45: https://luxhomme.store/products/ufit-2d?utm_source=yandex&utm_medium=cpc&utm_campaign=lux_search_vibro_{campaign_id}&utm_content=ufit-2d_{ad_id}_{source_type}&utm_term={keyword}
A47: Быстрые ссылки
A48: Название | B48: Описание | C48: ≤60 | D48: Ссылка (UTM) | H48: Название ≤30
...

Sheet uFit 2D Pro
A1: Виброплатформа uFit 2D Pro с EMS токами
A2: Страница | B2: https://luxhomme.store/products/ufit-2d-ems
A3: SKU | B3: VIPLATEL2D
A4: Цена, ₽ | B4: 7490
A5: С промокодом, ₽ | B5: =ROUND(B4*(1-Товары!$B$1),0)
A6: Промокод | B6: DIRECT20
A7: Категория | B7: Виброплатформы
A9: УТП (факты из карточки)
A10: • | B10: Вибрация + EMS + обогрев
A11: • | B11: 5 программ, 180 уровней скорости, амплитуда 0–12 мм
A12: • | B12: Нагрузка до 150 кг, 200 Вт
A13: • | B13: Фитнес-браслет и пульт ДУ
A14: • | B14: Bluetooth, динамик, голосовое сопровождение
A15: • | B15: Эспандеры, фитнес-резинка, план питания и тренировок в подарок
A16: • | B16: Гарантия 3 года
A18: Семантика
A19: Группа | B19: Фраза
A20: Тип + покупка | B20: виброплатформа с ems купить
A21: Тип + покупка | B21: виброплатформа для дома купить
A22: Тип + покупка | B22: виброплатформа ems цена
A23: Характеристики | B23: виброплатформа с ems
A24: Характеристики | B24: виброплатформа с миостимуляцией
A25: Характеристики | B25: виброплатформа с подогревом
A26: Характеристики | B26: виброплатформа с нагревом
A27: Характеристики | B27: виброплатформа с браслетом
A28: Характеристики | B28: вибротренажер с ems
A29: Характеристики | B29: виброплатформа 2d ems
A30: Характеристики | B30: виброплатформа с bluetooth
... A34: Модель | B34: ufit ems
A36: Минус-слова товара (+ общие и конкуренты — лист «Минус-слова»)
A37: Товар | B37: 3d, вред, противопоказания, польза, врачей, спортзал, аренда, лица, пояс, шорты
A38: Конкуренты | B38: bradex, брадекс, torneo, торнео, clear fit, planta, планта, oxygen, hasttings, evo fitness, proxima, dfc, body sculpture, unix fit, юникс, yamaguchi, ямагучи, casada, gezatone, us medica
A40: Объявления — Поиск
A41: № | B41: Заголовок 1 | C41: ≤56 | D41: Заголовок 2 | E41: ≤30 | F41: Текст | G41: ≤81 | H41: Отображаемая ссылка (≤20)
A42: 1 | B42: Виброплатформа uFit 2D Pro с EMS и обогревом | C42: =LEN(B42) | D42: Скидка 20% на сайте | E42: =LEN(D42) | F42: 5 программ, 180 скоростей, до 150 кг, 200 Вт. Промокод DIRECT20. | G42: =LEN(F42) | H42: uFit-2D-Pro-EMS
A43: 2 | B43: Виброплатформа с EMS для домашних тренировок | C43: =LEN(B43) | D43: Скидка 20% по промокоду | E43: =LEN(D43) | F43: uFit 2D Pro: браслет, эспандеры, планы тренировок и питания. Гарантия 3 года. | G43: =LEN(F43) | H43: uFit-2D-Pro-EMS
A44: 3 | B44: Купить виброплатформу с EMS за 5 992 ₽ | C44: =LEN(B44) | D44: Промокод DIRECT20 | E44: =LEN(D44) | F44: Вибрация, EMS и обогрев в одном тренажёре. Нагрузка до 150 кг. | G44: =LEN(F44) | H44: uFit-2D-Pro-EMS
A45: Ссылка (UTM) | B45: https://luxhomme.store/products/ufit-2d-ems?utm_source=yandex&utm_medium=cpc&utm_campaign=lux_search_vibro_{campaign_id}&utm_content=ufit-2d-pro-ems_{ad_id}_{source_type}&utm_term={keyword}
A47: Быстрые ссылки
A48: Название | B48: Описание | C48: ≤60 | D48: Ссылка (UTM) | H48: Название ≤30
...

Sheet uFit 3D Max
A1: Виброплатформа для похудения 3D c EMS токами и нагревом, нагрузка до 150 кг
A2: Страница | B2: https://luxhomme.store/products/vibroplatforma-dlya-pohudeniya-3d-c-ems-tokami-i-nagrevom-do-150-kg
A3: SKU | B3: нет в разметке сайта
A4: Цена, ₽ | B4: 16990
A5: С промокодом, ₽ | B5: =ROUND(B4*(1-Товары!$B$1),0)
A6: Промокод | B6: DIRECT20
A7: Категория | B7: Виброплатформы
A9: УТП (факты из карточки)
A10: • | B10: 3 технологии: 3D-вибрация, EMS, нагрев
A11: • | B11: 400 Вт, нагрузка до 150 кг
A12: • | B12: Bluetooth-браслет и пульт ДУ
A13: • | B13: Музыка по Bluetooth
A14: • | B14: Антискользящее покрытие, без поручней — компактно
A15: • | B15: Эспандеры, резинка, план тренировок и питания
A16: • | B16: Гарантия 3 года
A18: Семантика
A19: Группа | B19: Фраза
A20: Тип + покупка | B20: виброплатформа 3d купить
A21: Тип + покупка | B21: виброплатформа купить
A22: Тип + покупка | B22: виброплатформа для дома купить
A23: Характеристики | B23: виброплатформа 3d
A24: Характеристики | B24: 3d виброплатформа для дома
A25: Характеристики | B25: виброплатформа 3d с ems
A26: Характеристики | B26: виброплатформа с ems и нагревом
A27: Характеристики | B27: виброплатформа с bluetooth
A28: Характеристики | B28: мощная виброплатформа
A29: Характеристики | B29: виброплатформа 400 вт
A30: Характеристики | B30: вибротренажер 3d
... A34: Модель | B34: ufit 3d
A36: Минус-слова товара (+ общие и конкуренты — лист «Минус-слова»)
A37: Товар | B37: 2d, вред, противопоказания, польза, врачей, спортзал, аренда, лица, пояс, шорты
A38: Конкуренты | B38: bradex, брадекс, torneo, торнео, clear fit, planta, планта, oxygen, hasttings, evo fitness, proxima, dfc, body sculpture, unix fit, юникс, yamaguchi, ямагучи, casada, gezatone, us medica
A40: Объявления — Поиск
A41: № | B41: Заголовок 1 | C41: ≤56 | D41: Заголовок 2 | E41: ≤30 | F41: Текст | G41: ≤81 | H41: Отображаемая ссылка (≤20)
A42: 1 | B42: Виброплатформа 3D с EMS и нагревом — скидка 20% | C42: =LEN(B42) | D42: Промокод DIRECT20 | E42: =LEN(D42) | F42: uFit 3D Max: 400 Вт, Bluetooth-браслет и пульт. Нагрузка до 150 кг. | G42: =LEN(F42) | H42: uFit-3D-Max
A43: 2 | B43: Виброплатформа uFit 3D Max: вибрация, EMS, нагрев | C43: =LEN(B43) | D43: Скидка 20% на сайте | E43: =LEN(D43) | F43: 400 Вт, музыка по Bluetooth, антискользящее покрытие. Гарантия 3 года. | G43: =LEN(F43) | H43: uFit-3D-Max
A44: 3 | B44: Купить виброплатформу 3D с EMS за 13 592 ₽ | C44: =LEN(B44) | D44: Промокод DIRECT20 | E44: =LEN(D44) | F44: Мощность 400 Вт, нагрузка до 150 кг, эспандеры и план тренировок. | G44: =LEN(F44) | H44: uFit-3D-Max
A45: Ссылка (UTM) | B45: https://luxhomme.store/products/vibroplatforma-dlya-pohudeniya-3d-c-ems-tokami-i-nagrevom-do-150-kg?utm_source=yandex&utm_medium=cpc&utm_campaign=lux_search_vibro_{campaign_id}&utm_content=ufit-3d-max_{ad_id}_{source_type}&utm_term={keyword}
A47: Быстрые ссылки
A48: Название | B48: Описание | C48: ≤60 | D48: Ссылка (UTM) | H48: Название ≤30
...

Sheet uClean Max
A1: Робот мойщик Luxhommè uClean Max
A2: Страница | B2: https://luxhomme.store/products/window
A3: SKU | B3: ROBOTOKONKVADR
A4: Цена, ₽ | B4: 9990
A5: С промокодом, ₽ | B5: =ROUND(B4*(1-Товары!$B$1),0)
A6: Промокод | B6: DIRECT20
A7: Категория | B7: Роботы-мойщики окон
A9: УТП (факты из карточки)
A10: • | B10: Двойное автоматическое распыление
A11: • | B11: Всасывание 3000 Па
A12: • | B12: Приложение iOS/Android и пульт ДУ
A13: • | B13: 3 маршрута: Z, N и двойной
A14: • | B14: 2,5–3 минуты на 1 м²
A15: • | B15: Страховочный трос 5 м (до 150 кг), 40 минут на стекле при отключении питания
A16: • | B16: Безрамочные поверхности, голос на русском
A17: • | B17: В подарок: 5 доп. салфеток, арома-саше
A18: • | B18: Гарантия 3 года
A20: Семантика
A21: Группа | B21: Фраза
A22: Тип + покупка | B22: робот мойщик окон купить
A23: Тип + покупка | B23: робот для мытья окон купить
A24: Тип + покупка | B24: мойщик окон робот цена
A25: Тип + покупка | B25: робот для мытья окон
A26: Характеристики | B26: робот мойщик окон с распылением
A27: Характеристики | B27: робот для мытья окон с распылителем
A28: Характеристики | B28: робот мойщик окон квадратный
A29: Характеристики | B29: робот для мытья окон с пультом
A30: Характеристики | B30: робот мойщик окон с приложением
A31: Характеристики | B31: робот мойщик окон с тросом
A32: Назначение | B32: робот для мытья стекол
... A37: Модель | B37: робот uclean
A39: Минус-слова товара (+ общие и конкуренты — лист «Минус-слова»)
A40: Товар | B40: пылесос, газонокосилка, бассейн, бассейна, аквариум, солнечных, панелей, салфетки, жидкость, средство, промышленный, альпинист, услуги
A41: Конкуренты | B41: hobot, хобот, ecovacs, winbot, винбот, xiaomi, kitfort, китфорт, cecotec, mamibot, liectroux, hutt, atvel, атвел
A43: Объявления — Поиск
A44: № | B44: Заголовок 1 | C44: ≤56 | D44: Заголовок 2 | E44: ≤30 | F44: Текст | G44: ≤81 | H44: Отображаемая ссылка (≤20)
A45: 1 | B45: Робот-мойщик окон uClean Max с двойным распылением | C45: =LEN(B45) | D45: Скидка 20% на сайте | E45: =LEN(D45) | F45: 3000 Па, приложение и пульт, 3 маршрута, трос 5 м. Промокод DIRECT20. | G45: =LEN(F45) | H45: uClean-Max
A46: 2 | B46: Робот для мытья окон с приложением и пультом | C46: =LEN(B46) | D46: Скидка 20% по промокоду | E46: =LEN(D46) | F46: uClean Max: 2,5–3 минуты на 1 м², голос на русском. Гарантия 3 года. | G46: =LEN(F46) | H46: uClean-Max
A47: 3 | B47: Купить робот-мойщик окон uClean Max за 7 992 ₽ | C47: =LEN(B47) | D47: Промокод DIRECT20 | E47: =LEN(D47) | F47: Для безрамочных поверхностей. 40 минут на стекле при отключении питания. | G47: =LEN(F47) | H47: uClean-Max
A48: Ссылка (UTM) | B48: https://luxhomme.store/products/window?utm_source=yandex&utm_medium=cpc&utm_campaign=lux_search_okna_{campaign_id}&utm_content=uclean-max_{ad_id}_{source_type}&utm_term={keyword}
...

Sheet Минус-слова
A1: Общие — на все кампании
A2: Нецелевые | B2: бесплатно, скачать, своими руками, ремонт, запчасти, запчасть, комплектующие, разборка, схема, инструкция, руководство, неисправность, сломался, бу, авито, юла, аренда, прокат, напрокат, вакансия, работа, оптом, опт, реферат, фото, картинки, рисунок, игрушка, игрушечный, детский, раскраска, википедия
A3: Магазины и маркетплейсы | B3: озон, ozon, wildberries, вайлдберриз, валберис, вб, маркет, мегамаркет, днс, dns, мвидео, эльдорадо, ситилинк, леруа, ашан, aliexpress, алиэкспресс, temu
A4: Информационные (на старте) | B4: отзывы, отзыв, обзор, рейтинг, топ, лучший, сравнение, сравнить, какой, выбрать, видео
